Workbook

Sheet Original Data
A1: store_id | B1: month | C1: region | D1: store_type | E1: marketing_spend | F1: footfall | G1: avg_discount_pct | H1: staff_count | I1: inventory_availability_pct | J1: competitor_distance_km | K1: holiday_flag | L1: customer_rating | M1: monthly_sales | N1: monthly_profit
A2: STR-1001 | B2: 45658 | C2: East | D2: Residential | E2: 70389.11 | F2: 8302 | G2: 0.042 | H2: 17 | I2: 75 | J2: 5.28 | K2: 1 | L2: 3.1 | M2: 658832.62 | N2: 84349.93
A3: STR-1001 | B3: 45689 | C3: East | D3: Residential | E3: 43827.89 | F3: 8487 | G3: 0.168 | H3: 23 | I3: 84.4 | J3: 4.31 | K3: 0 | L3: 2.8 | M3: 634436 | N3: 106130.54
A4: STR-1001 | B4: 45717 | C4: East | D4: Residential | E4: 59921.75 | F4: 9113 | G4: 0.133 | H4: 20 | I4: 88 | J4: 12 | K4: 0 | L4: 3.2 | M4: 678722.06 | N4: 101883.86
A5: STR-1001 | B5: 45748 | C5: East | D5: Residential | E5: 56856.63 | F5: 9431 | G5: 0.142 | H5: 23 | I5: 86.9 | J5: 4.97 | K5: 0 | L5: 3.4 | M5: 658920.3 | N5: 97910.37
A6: STR-1002 | B6: 45658 | C6: East | D6: High Street | E6: 48412.64 | F6: 9545 | G6: 0.231 | H6: 21 | I6: 97.6 | J6: 6.94 | K6: 1 | L6: 4.2 | M6: 741341.44 | N6: 119208.17
A7: STR-1002 | B7: 45689 | C7: East | D7: High Street | E7: 64811.21 | F7: 9792 | G7: 0.112 | H7: 20 | I7: 84.2 | J7: 2.88 | K7: 0 | L7: 4.2 | M7: 761835.34 | N7: 149602.23
A8: STR-1002 | B8: 45717 | C8: East | D8: High Street | E8: 46213.45 | F8: 10616 | G8: 0.122 | H8: 22 | I8: 85.2 | J8: 0.2 | K8: 1 | L8: 4.1 | M8: 806615.54 | N8: 131364.62
A9: STR-1002 | B9: 45748 | C9: East | D9: High Street | E9: 68148.52 | F9: 8567 | G9: 0.127 | H9: 23 | I9: 95.6 | J9: 0.8 | K9: 0 | L9: 3.9 | M9: 850164.26 | N9: 149262.75
A10: STR-1003 | B10: 45658 | C10: North | D10: Airport | E10: 71838.86 | F10: 10979 | G10: 0.215 | H10: 26 | I10: 88.6 | J10: 7.7 | K10: 1 | L10: 3.8 | M10: 930581.7 | N10: 136207.98
A11: STR-1003 | B11: 45689 | C11: North | D11: Airport | E11: 68133.44 | F11: 9459 | G11: 0.22 | H11: 21 | I11: 85 | J11: 1.91 | K11: 0 | L11: 4.2 | M11: 779010.94 | N11: 106328.09
A12: STR-1003 | B12: 45717 | C12: North | D12: Airport | E12: 34285.21 | F12: 9172 | G12: 0.213 | H12: 22 | I12: 88.3 | J12: 10.46 | K12: 1 | L12: 3.8 | M12: 723060.76 | N12: 123131.24
A13: STR-1003 | B13: 45748 | C13: North | D13: Airport | E13: 67979.88 | F13: 11230 | G13: 0.002 | H13: 28 | I13: 85.3 | J13: 7.16 | K13: 0 | L13: 3.8 | M13: 910791.94 | N13: 158891.28
... A34: STR-1009 | B34: 45658 | C34: North | D34: Residential | E34: 54597.83 | F34: 9429 | G34: 0.188 | H34: 21 | I34: 83.3 | J34: 11.71 | K34: 0 | L34: 4.2 | M34: 641865.03 | N34: 81342.58
A35: STR-1009 | B35: 45689 | C35: North | D35: Residential | E35: 73771.91 | F35: 11695 | G35: 0.07 | H35: 25 | I35: 84.7 | J35: 0.62 | K35: 0 | M35: 799477.76 | N35: 164974.41
A36: STR-1009 | B36: 45717 | C36: North | D36: Residential | E36: 74413.88 | F36: 9449 | G36: 0.039 | H36: 23 | I36: 92.1 | J36: 2.12 | K36: 0 | L36: 3.5 | M36: 798952.17 | N36: 161499.04
A37: STR-1009 | B37: 45748 | C37: North | D37: Residential | E37: 52483.77 | F37: 10453 | G37: 0.247 | H37: 25 | I37: 99 | J37: 6.31 | K37: 0 | L37: 3.6 | M37: 800979.78 | N37: 149242.27
A38: STR-1010 | B38: 45658 | C38: North | D38: Mall | E38: 75269.87 | F38: 8838 | G38: 0.092 | H38: 21 | I38: 83.1 | J38: 9.56 | K38: 1 | L38: 4.2 | M38: 820593.93 | N38: 115860.06
A39: STR-1010 | B39: 45689 | C39: North | D39: Mall | E39: 61245.41 | F39: 8156 | G39: 0.156 | H39: 19 | I39: 92.9 | J39: 9.05 | K39: 0 | L39: 3.8 | M39: 718330.53 | N39: 93247.9
A40: STR-1010 | B40: 45717 | C40: North | D40: Mall | E40: 93381.26 | F40: 7562 | G40: 0.198 | H40: 19 | I40: 82.9 | J40: 5.05 | K40: 0 | L40: 4 | M40: 736633.4 | N40: 115654.66
A41: STR-1010 | B41: 45748 | C41: North | D41: Mall | E41: 65012.19 | F41: 9598 | G41: 0.085 | H41: 24 | I41: 98.3 | J41: 0.89 | K41: 0 | L41: 3.8 | M41: 828623.85 | N41: 167320.52
A42: STR-1011 | B42: 45658 | C42: East | D42: Mall | E42: 40462.94 | F42: 3660 | G42: 0.218 | H42: 11 | I42: 95.2 | J42: 5.57 | K42: 0 | L42: 4.4 | M42: 592195.85 | N42: 92291.56
A43: STR-1011 | B43: 45689 | C43: East | D43: Mall | E43: 46123.88 | F43: 3227 | G43: 0.143 | H43: 10 | I43: 75.4 | J43: 1.06 | K43: 0 | L43: 4.4 | M43: 532644.46 | N43: 60681.32
A44: STR-1011 | B44: 45717 | C44: East | D44: Mall | E44: 68077.54 | F44: 3360 | G44: 0.128 | H44: 14 | I44: 88.2 | J44: 1.24 | K44: 1 | L44: 4 | M44: 657429.18 | N44: 88919.74
A45: STR-1011 | B45: 45748 | C45: East | D45: Mall | E45: 64882.14 | F45: 3642 | G45: 0.019 | H45: 13 | I45: 87.8 | J45: 4.52 | K45: 0 | L45: 4.2 | M45: 605178 | N45: 106958.74
A46: STR-1012 | B46: 45658 | C46: West | D46: Residential | E46: 138855.51 | F46: 5145 | G46: 0.06 | H46: 17 | I46: 88.2 | J46: 9.58 | K46: 0 | L46: 3.2 | M46: 595467.6 | N46: 104276.46
A47: STR-1012 | B47: 45689 | C47: West | D47: Residential | E47: 63630.21 | F47: 4460 | G47: 0.235 | H47: 14 | I47: 98.6 | J47: 5.52 | K47: 0 | L47: 3.5 | M47: 599603.4 | N47: 112685.12
... A72: STR-1018 | B72: 45717 | C72: East | D72: High Street | E72: 60571.82 | F72: 3193 | G72: 0.197 | H72: 7 | I72: 99 | J72: 1.43 | K72: 0 | L72: 3.2 | M72: 605023.87 | N72: 98545.81
A73: STR-1018 | B73: 45748 | C73: East | D73: High Street | E73: 55081.16 | F73: 5485 | G73: 0.036 | H73: 12 | I73: 88 | K73: 0 | L73: 3.5 | M73: 674774.09 | N73: 141917.59
A74: STR-1019 | B74: 45658 | C74: East | D74: Residential | E74: 46201.46 | F74: 5918 | G74: 0.277 | H74: 13 | I74: 78.8 | J74: 4.91 | K74: 0 | L74: 4.5 | M74: 616069.41 | N74: 54453.99
A75: STR-1019 | B75: 45689 | C75: East | D75: Residential | E75: 53762.92 | F75: 6821 | G75: 0.066 | H75: 19 | I75: 94.6 | J75: 7.03 | K75: 0 | L75: 4.4 | M75: 630829.94 | N75: 117090.02
A76: STR-1019 | B76: 45717 | C76: East | D76: Residential | E76: 70144.78 | F76: 6806 | G76: 0.178 | H76: 20 | I76: 93.1 | J76: 0.28 | K76: 1 | L76: 4.3 | M76: 788087.68 | N76: 116803.42
A77: STR-1019 | B77: 45748 | C77: East | D77: Residential | E77: 58749.63 | F77: 8252 | G77: 0.203 | H77: 20 | I77: 85.2 | J77: 3.61 | K77: 0 | L77: 4.5 | M77: 680840.36 | N77: 68007.68
A78: STR-1020 | B78: 45658 | C78: South | D78: High Street | E78: 56973.18 | F78: 6662 | G78: 0.1 | H78: 15 | I78: 77.7 | J78: 7.52 | K78: 1 | L78: 3.2 | M78: 643657.47 | N78: 87022.45
A79: STR-1020 | B79: 45689 | C79: South | D79: High Street | E79: 54872.82 | F79: 5962 | G79: 0.064 | H79: 12 | I79: 85.4 | J79: 2.58 | K79: 0 | L79: 2.9 | M79: 691112.6 | N79: 109212.83
A80: STR-1020 | B80: 45717 | C80: South | D80: High Street | E80: 80562.81 | F80: 7470 | G80: 0.172 | H80: 16 | I80: 83.5 | J80: 2.29 | K80: 0 | L80: 3.3 | M80: 776922.17 | N80: 150701.93
A81: STR-1020 | B81: 45748 | C81: South | D81: High Street | E81: 77999.9 | F81: 5974 | G81: 0.252 | H81: 14 | I81: 81.3 | J81: 2.39 | K81: 0 | L81: 3.2 | M81: 636561.34 | N81: 93861.06
A82: STR-1021 | B82: 45658 | C82: West | D82: Mall | E82: 60881.01 | F82: 5410 | G82: 0.179 | H82: 15 | I82: 83.9 | J82: 5.24 | K82: 0 | L82: 4.6 | M82: 621369.58 | N82: 85493.64
A83: STR-1021 | B83: 45689 | C83: West | D83: Mall | E83: 60628.38 | F83: 4451 | G83: 0.095 | H83: 10 | I83: 89.6 | J83: 3.17 | K83: 0 | L83: 4.6 | M83: 682208.01 | N83: 110318.84
A84: STR-1021 | B84: 45717 | C84: West | D84: Mall | E84: 72731.14 | F84: 4644 | G84: 0.084 | H84: 15 | I84: 87.1 | J84: 2.66 | K84: 0 | L84: 4.6 | M84: 727241.86 | N84: 155810.3
...

Sheet Cleaned Data
A1: store_id | B1: month | C1: region | D1: store_type | E1: marketing_spend | F1: footfall | G1: avg_discount_pct | H1: staff_count | I1: inventory_availability_pct | J1: competitor_distance_km | K1: holiday_flag | L1: customer_rating | M1: monthly_sales | N1: monthly_profit
A2: STR-1001 | B2: 45658 | C2: East | D2: Residential | E2: 70389.11 | F2: 8302 | G2: 0.042 | H2: 17 | I2: 75 | J2: 5.28 | K2: 1 | L2: 3.1 | M2: 658832.62 | N2: 84349.93
A3: STR-1001 | B3: 45689 | C3: East | D3: Residential | E3: 43827.89 | F3: 8487 | G3: 0.168 | H3: 23 | I3: 84.4 | J3: 4.31 | K3: 0 | L3: 2.8 | M3: 634436 | N3: 106130.54
A4: STR-1001 | B4: 45717 | C4: East | D4: Residential | E4: 59921.75 | F4: 9113 | G4: 0.133 | H4: 20 | I4: 88 | J4: 12 | K4: 0 | L4: 3.2 | M4: 678722.06 | N4: 101883.86
A5: STR-1001 | B5: 45748 | C5: East | D5: Residential | E5: 56856.63 | F5: 9431 | G5: 0.142 | H5: 23 | I5: 86.9 | J5: 4.97 | K5: 0 | L5: 3.4 | M5: 658920.3 | N5: 97910.37
A6: STR-1002 | B6: 45658 | C6: East | D6: High Street | E6: 48412.64 | F6: 9545 | G6: 0.231 | H6: 21 | I6: 97.6 | J6: 6.94 | K6: 1 | L6: 4.2 | M6: 741341.44 | N6: 119208.17
A7: STR-1002 | B7: 45689 | C7: East | D7: High Street | E7: 64811.21 | F7: 9792 | G7: 0.112 | H7: 20 | I7: 84.2 | J7: 2.88 | K7: 0 | L7: 4.2 | M7: 761835.34 | N7: 149602.23
A8: STR-1002 | B8: 45717 | C8: East | D8: High Street | E8: 46213.45 | F8: 10616 | G8: 0.122 | H8: 22 | I8: 85.2 | J8: 0.2 | K8: 1 | L8: 4.1 | M8: 806615.54 | N8: 131364.62
A9: STR-1002 | B9: 45748 | C9: East | D9: High Street | E9: 68148.52 | F9: 8567 | G9: 0.127 | H9: 23 | I9: 95.6 | J9: 0.8 | K9: 0 | L9: 3.9 | M9: 850164.26 | N9: 149262.75
A10: STR-1003 | B10: 45658 | C10: North | D10: Airport | E10: 71838.86 | F10: 10979 | G10: 0.215 | H10: 26 | I10: 88.6 | J10: 7.7 | K10: 1 | L10: 3.8 | M10: 930581.7 | N10: 136207.98
A11: STR-1003 | B11: 45689 | C11: North | D11: Airport | E11: 68133.44 | F11: 9459 | G11: 0.22 | H11: 21 | I11: 85 | J11: 1.91 | K11: 0 | L11: 4.2 | M11: 779010.94 | N11: 106328.09
A12: STR-1003 | B12: 45717 | C12: North | D12: Airport | E12: 34285.21 | F12: 9172 | G12: 0.213 | H12: 22 | I12: 88.3 | J12: 10.46 | K12: 1 | L12: 3.8 | M12: 723060.76 | N12: 123131.24
A13: STR-1003 | B13: 45748 | C13: North | D13: Airport | E13: 67979.88 | F13: 11230 | G13: 0.002 | H13: 28 | I13: 85.3 | J13: 7.16 | K13: 0 | L13: 3.8 | M13: 910791.94 | N13: 158891.28
... A321: STR-1080 | B321: 45748 | C321: East | D321: Residential | E321: 40553.11 | F321: 5317 | G321: 0.165 | H321: 17 | I321: 84.3 | J321: 11.82 | K321: 0 | L321: 4.1 | M321: 559660.84 | N321: 71443.61

Sheet Dummy Variables
A1: monthly_sales | B1: marketing_spend | C1: footfall | D1: avg_discount_pct | E1: staff_count | F1: inventory_availability_pct | G1: competitor_distance_km | H1: holiday_flag | I1: customer_rating | J1: is_east | K1: is_west | L1: is_north | M1: is_airport | N1: is_high_street | O1: is_mall
A2: 658832.62 | B2: 70389.11 | C2: 8302 | D2: 0.042 | E2: 17 | F2: 75 | G2: 5.28 | H2: 1 | I2: 3.1 | J2: =IF('Cleaned Data'!C2 = "East", 1, 0) -> 1 | K2: =IF('Cleaned Data'!C2 = "West", 1, 0) -> 0 | L2: =IF('Cleaned Data'!C2 = "North", 1, 0) -> 0 | M2: =IF('Cleaned Data'!D2 = "Airport", 1, 0) -> 0 | N2: =IF('Cleaned Data'!D2 = "High Street", 1,0) -> 0 | O2: =IF('Cleaned Data'!D2 = "Mall", 1,0) -> 0 | Q2: Colour Codes:
A3: 634436 | B3: 43827.89 | C3: 8487 | D3: 0.168 | E3: 23 | F3: 84.4 | G3: 4.31 | H3: 0 | I3: 2.8 | J3: =IF('Cleaned Data'!C3 = "East", 1, 0) -> 1 | K3: =IF('Cleaned Data'!C3 = "West", 1, 0) -> 0 | L3: =IF('Cleaned Data'!C3 = "North", 1, 0) -> 0 | M3: =IF('Cleaned Data'!D3 = "Airport", 1, 0) -> 0 | N3: =IF('Cleaned Data'!D3 = "High Street", 1,0) -> 0 | O3: =IF('Cleaned Data'!D3 = "Mall", 1,0) -> 0 | Q3: Dependent Variable (Y)
A4: 678722.06 | B4: 59921.75 | C4: 9113 | D4: 0.133 | E4: 20 | F4: 88 | G4: 12 | H4: 0 | I4: 3.2 | J4: =IF('Cleaned Data'!C4 = "East", 1, 0) -> 1 | K4: =IF('Cleaned Data'!C4 = "West", 1, 0) -> 0 | L4: =IF('Cleaned Data'!C4 = "North", 1, 0) -> 0 | M4: =IF('Cleaned Data'!D4 = "Airport", 1, 0) -> 0 | N4: =IF('Cleaned Data'!D4 = "High Street", 1,0) -> 0 | O4: =IF('Cleaned Data'!D4 = "Mall", 1,0) -> 0 | Q4: Independent Variables (X)
A5: 658920.3 | B5: 56856.63 | C5: 9431 | D5: 0.142 | E5: 23 | F5: 86.9 | G5: 4.97 | H5: 0 | I5: 3.4 | J5: =IF('Cleaned Data'!C5 = "East", 1, 0) -> 1 | K5: =IF('Cleaned Data'!C5 = "West", 1, 0) -> 0 | L5: =IF('Cleaned Data'!C5 = "North", 1, 0) -> 0 | M5: =IF('Cleaned Data'!D5 = "Airport", 1, 0) -> 0 | N5: =IF('Cleaned Data'!D5 = "High Street", 1,0) -> 0 | O5: =IF('Cleaned Data'!D5 = "Mall", 1,0) -> 0 | Q5: Dummy Variables
A6: 741341.44 | B6: 48412.64 | C6: 9545 | D6: 0.231 | E6: 21 | F6: 97.6 | G6: 6.94 | H6: 1 | I6: 4.2 | J6: =IF('Cleaned Data'!C6 = "East", 1, 0) -> 1 | K6: =IF('Cleaned Data'!C6 = "West", 1, 0) -> 0 | L6: =IF('Cleaned Data'!C6 = "North", 1, 0) -> 0 | M6: =IF('Cleaned Data'!D6 = "Airport", 1, 0) -> 0 | N6: =IF('Cleaned Data'!D6 = "High Street", 1,0) -> 1 | O6: =IF('Cleaned Data'!D6 = "Mall", 1,0) -> 0
A7: 761835.34 | B7: 64811.21 | C7: 9792 | D7: 0.112 | E7: 20 | F7: 84.2 | G7: 2.88 | H7: 0 | I7: 4.2 | J7: =IF('Cleaned Data'!C7 = "East", 1, 0) -> 1 | K7: =IF('Cleaned Data'!C7 = "West", 1, 0) -> 0 | L7: =IF('Cleaned Data'!C7 = "North", 1, 0) -> 0 | M7: =IF('Cleaned Data'!D7 = "Airport", 1, 0) -> 0 | N7: =IF('Cleaned Data'!D7 = "High Street", 1,0) -> 1 | O7: =IF('Cleaned Data'!D7 = "Mall", 1,0) -> 0
A8: 806615.54 | B8: 46213.45 | C8: 10616 | D8: 0.122 | E8: 22 | F8: 85.2 | G8: 0.2 | H8: 1 | I8: 4.1 | J8: =IF('Cleaned Data'!C8 = "East", 1, 0) -> 1 | K8: =IF('Cleaned Data'!C8 = "West", 1, 0) -> 0 | L8: =IF('Cleaned Data'!C8 = "North", 1, 0) -> 0 | M8: =IF('Cleaned Data'!D8 = "Airport", 1, 0) -> 0 | N8: =IF('Cleaned Data'!D8 = "High Street", 1,0) -> 1 | O8: =IF('Cleaned Data'!D8 = "Mall", 1,0) -> 0
A9: 850164.26 | B9: 68148.52 | C9: 8567 | D9: 0.127 | E9: 23 | F9: 95.6 | G9: 0.8 | H9: 0 | I9: 3.9 | J9: =IF('Cleaned Data'!C9 = "East", 1, 0) -> 1 | K9: =IF('Cleaned Data'!C9 = "West", 1, 0) -> 0 | L9: =IF('Cleaned Data'!C9 = "North", 1, 0) -> 0 | M9: =IF('Cleaned Data'!D9 = "Airport", 1, 0) -> 0 | N9: =IF('Cleaned Data'!D9 = "High Street", 1,0) -> 1 | O9: =IF('Cleaned Data'!D9 = "Mall", 1,0) -> 0
A10: 930581.7 | B10: 71838.86 | C10: 10979 | D10: 0.215 | E10: 26 | F10: 88.6 | G10: 7.7 | H10: 1 | I10: 3.8 | J10: =IF('Cleaned Data'!C10 = "East", 1, 0) -> 0 | K10: =IF('Cleaned Data'!C10 = "West", 1, 0) -> 0 | L10: =IF('Cleaned Data'!C10 = "North", 1, 0) -> 1 | M10: =IF('Cleaned Data'!D10 = "Airport", 1, 0) -> 1 | N10: =IF('Cleaned Data'!D10 = "High Street", 1,0) -> 0 | O10: =IF('Cleaned Data'!D10 = "Mall", 1,0) -> 0
A11: 779010.94 | B11: 68133.44 | C11: 9459 | D11: 0.22 | E11: 21 | F11: 85 | G11: 1.91 | H11: 0 | I11: 4.2 | J11: =IF('Cleaned Data'!C11 = "East", 1, 0) -> 0 | K11: =IF('Cleaned Data'!C11 = "West", 1, 0) -> 0 | L11: =IF('Cleaned Data'!C11 = "North", 1, 0) -> 1 | M11: =IF('Cleaned Data'!D11 = "Airport", 1, 0) -> 1 | N11: =IF('Cleaned Data'!D11 = "High Street", 1,0) -> 0 | O11: =IF('Cleaned Data'!D11 = "Mall", 1,0) -> 0
A12: 723060.76 | B12: 34285.21 | C12: 9172 | D12: 0.213 | E12: 22 | F12: 88.3 | G12: 10.46 | H12: 1 | I12: 3.8 | J12: =IF('Cleaned Data'!C12 = "East", 1, 0) -> 0 | K12: =IF('Cleaned Data'!C12 = "West", 1, 0) -> 0 | L12: =IF('Cleaned Data'!C12 = "North", 1, 0) -> 1 | M12: =IF('Cleaned Data'!D12 = "Airport", 1, 0) -> 1 | N12: =IF('Cleaned Data'!D12 = "High Street", 1,0) -> 0 | O12: =IF('Cleaned Data'!D12 = "Mall", 1,0) -> 0
A13: 910791.94 | B13: 67979.88 | C13: 11230 | D13: 0.002 | E13: 28 | F13: 85.3 | G13: 7.16 | H13: 0 | I13: 3.8 | J13: =IF('Cleaned Data'!C13 = "East", 1, 0) -> 0 | K13: =IF('Cleaned Data'!C13 = "West", 1, 0) -> 0 | L13: =IF('Cleaned Data'!C13 = "North", 1, 0) -> 1 | M13: =IF('Cleaned Data'!D13 = "Airport", 1, 0) -> 1 | N13: =IF('Cleaned Data'!D13 = "High Street", 1,0) -> 0 | O13: =IF('Cleaned Data'!D13 = "Mall", 1,0) -> 0
A14: 922168.6 | B14: 71828.26 | C14: 12775 | D14: 0.116 | E14: 30 | F14: 81.7 | G14: 4.24 | H14: 1 | I14: 4.2 | J14: =IF('Cleaned Data'!C14 = "East", 1, 0) -> 1 | K14: =IF('Cleaned Data'!C14 = "West", 1, 0) -> 0 | L14: =IF('Cleaned Data'!C14 = "North", 1, 0) -> 0 | M14: =IF('Cleaned Data'!D14 = "Airport", 1, 0) -> 0 | N14: =IF('Cleaned Data'!D14 = "High Street", 1,0) -> 0 | O14: =IF('Cleaned Data'!D14 = "Mall", 1,0) -> 0
A15: 726606.28 | B15: 55716.82 | C15: 10054 | D15: 0.146 | E15: 24 | F15: 84.9 | G15: 1.06 | H15: 0 | I15: 4.3 | J15: =IF('Cleaned Data'!C15 = "East", 1, 0) -> 1 | K15: =IF('Cleaned Data'!C15 = "West", 1, 0) -> 0 | L15: =IF('Cleaned Data'!C15 = "North", 1, 0) -> 0 | M15: =IF('Cleaned Data'!D15 = "Airport", 1, 0) -> 0 | N15: =IF('Cleaned Data'!D15 = "High Street", 1,0) -> 0 | O15: =IF('Cleaned Data'!D15 = "Mall", 1,0) -> 0
A16: 746501.09 | B16: 59909.51 | C16: 8895 | D16: 0.228 | E16: 23 | F16: 88.8 | G16: 0.27 | H16: 0 | I16: 4.3 | J16: =IF('Cleaned Data'!C16 = "East", 1, 0) -> 1 | K16: =IF('Cleaned Data'!C16 = "West", 1, 0) -> 0 | L16: =IF('Cleaned Data'!C16 = "North", 1, 0) -> 0 | M16: =IF('Cleaned Data'!D16 = "Airport", 1, 0) -> 0 | N16: =IF('Cleaned Data'!D16 = "High Street", 1,0) -> 0 | O16: =IF('Cleaned Data'!D16 = "Mall", 1,0) -> 0
A17: 834017.02 | B17: 75305.71 | C17: 10940 | D17: 0.006 | E17: 26 | F17: 76.5 | G17: 1.32 | H17: 0 | I17: 4.5 | J17: =IF('Cleaned Data'!C17 = "East", 1, 0) -> 1 | K17: =IF('Cleaned Data'!C17 = "West", 1, 0) -> 0 | L17: =IF('Cleaned Data'!C17 = "North", 1, 0) -> 0 | M17: =IF('Cleaned Data'!D17 = "Airport", 1, 0) -> 0 | N17: =IF('Cleaned Data'!D17 = "High Street", 1,0) -> 0 | O17: =IF('Cleaned Data'!D17 = "Mall", 1,0) -> 0
... A321: 559660.84 | B321: 40553.11 | C321: 5317 | D321: 0.165 | E321: 17 | F321: 84.3 | G321: 11.82 | H321: 0 | I321: 4.1 | J321: =IF('Cleaned Data'!C321 = "East", 1, 0) -> 1 | K321: =IF('Cleaned Data'!C321 = "West", 1, 0) -> 0 | L321: =IF('Cleaned Data'!C321 = "North", 1, 0) -> 0 | M321: =IF('Cleaned Data'!D321 = "Airport", 1, 0) -> 0 | N321: =IF('Cleaned Data'!D321 = "High Street", 1,0) -> 0 | O321: =IF('Cleaned Data'!D321 = "Mall", 1,0) -> 0

Sheet Simple Regression
A1: SUMMARY OUTPUT
A2: Simple Regression for marketing_spend as Independent Variable
A3: Regression Statistics
A4: Multiple R | B4: 0.40895561
A5: R Square | B5: 0.16724469
A6: Adjusted R Square | B6: 0.16462596
A7: Standard Error | B7: 94846.034
A8: Observations | B8: 320
A10: ANOVA
B11: df | C11: SS | D11: MS | E11: F | F11: Significance F
A12: Regression | B12: 1 | C12: 5.7451371e+11 | D12: 5.7451371e+11 | E12: 63.864873 | F12: 2.4800615e-14
A13: Residual | B13: 318 | C13: 2.8606549e+12 | D13: 8.9957701e+09
A14: Total | B14: 319 | C14: 3.4351686e+12
B16: Coefficients | C16: Standard Error | D16: t Stat | E16: P-value | F16: Lower 95% | G16: Upper 95% | H16: Lower 95.0% | I16: Upper 95.0%
A17: Intercept | B17: 560777.35 | C17: 15906.906 | D17: 35.253703 | E17: 6.9528769e-112 | F17: 529481.27 | G17: 592073.42 | H17: 529481.27 | I17: 592073.42
A18: marketing_spend | B18: 2.1295753 | C18: 0.26647838 | D18: 7.9915501 | E18: 2.4800615e-14 | F18: 1.6052919 | G18: 2.6538587 | H18: 1.6052919 | I18: 2.6538587
A21: Simple Regression for footfall as Independent Variable
A22: SUMMARY OUTPUT
A24: Regression Statistics
A25: Multiple R | B25: 0.85807071
A26: R Square | B26: 0.73628534
A27: Adjusted R Square | B27: 0.73545605
A28: Standard Error | B28: 53373.736
A29: Observations | B29: 320
A31: ANOVA
B32: df | C32: SS | D32: MS | E32: F | F32: Significance F
A33: Regression | B33: 1 | C33: 2.5292643e+12 | D33: 2.5292643e+12 | E33: 887.84878 | F33: 4.7503615e-94
A34: Residual | B34: 318 | C34: 9.0590432e+11 | D34: 2.8487557e+09
A35: Total | B35: 319 | C35: 3.4351686e+12
B37: Coefficients | C37: Standard Error | D37: t Stat | E37: P-value | F37: Lower 95% | G37: Upper 95% | H37: Lower 95.0% | I37: Upper 95.0%
A38: Intercept | B38: 446410.58 | C38: 8407.7383 | D38: 53.095205 | E38: 4.0862696e-160 | F38: 429868.76 | G38: 462952.4 | H38: 429868.76 | I38: 462952.4
A39: footfall | B39: 35.678031 | C39: 1.1973783 | D39: 29.796791 | E39: 4.7503615e-94 | F39: 33.322247 | G39: 38.033815 | H39: 33.322247 | I39: 38.033815

Sheet Multiple Regression
A1: SUMMARY OUTPUT
A3: Regression Statistics
A4: Multiple R | B4: 0.92577345
A5: R Square | B5: 0.85705649
A6: Adjusted R Square | B6: 0.85049515
A7: Standard Error | B7: 40124.195
A8: Observations | B8: 320
A10: ANOVA
B11: df | C11: SS | D11: MS | E11: F | F11: Significance F
A12: Regression | B12: 14 | C12: 2.9441335e+12 | D12: 2.1029525e+11 | E12: 130.62214 | F12: 1.1607311e-119
A13: Residual | B13: 305 | C13: 4.9103507e+11 | D13: 1.609951e+09
A14: Total | B14: 319 | C14: 3.4351686e+12
B16: Coefficients | C16: Standard Error | D16: t Stat | E16: P-value | F16: Lower 95% | G16: Upper 95% | H16: Lower 95.0% | I16: Upper 95.0%
A17: Intercept | B17: 62219.717 | C17: 45404.93 | D17: 1.3703295 | E17: 0.1715918 | F17: -27126.849 | G17: 151566.28 | H17: -27126.849 | I17: 151566.28
A18: marketing_spend | B18: 1.210569 | C18: 0.11692032 | D18: 10.353795 | E18: 9.9893911e-22 | F18: 0.98049642 | G18: 1.4406416 | H18: 0.98049642 | I18: 1.4406416
A19: footfall | B19: 27.329869 | C19: 2.3058298 | D19: 11.852509 | E19: 6.5486276e-27 | F19: 22.79252 | G19: 31.867217 | H19: 22.79252 | I19: 31.867217
A20: avg_discount_pct | B20: -41094.404 | C20: 33866.729 | D20: -1.2134152 | E20: 0.22590997 | F20: -107736.42 | G20: 25547.609 | H20: -107736.42 | I20: 25547.609
A21: staff_count | B21: 3510.8391 | C21: 1161.5433 | D21: 3.0225642 | E21: 0.0027190242 | F21: 1225.1863 | G21: 5796.4918 | H21: 1225.1863 | I21: 5796.4918
A22: inventory_availability_pct | B22: 3062.3887 | C22: 425.9883 | D22: 7.1889032 | E22: 5.0591929e-12 | F22: 2224.1407 | G22: 3900.6367 | H22: 2224.1407 | I22: 3900.6367
A23: competitor_distance_km | B23: -3439.3951 | C23: 540.13094 | D23: -6.3677062 | E23: 7.0453517e-10 | F23: -4502.2499 | G23: -2376.5404 | H23: -4502.2499 | I23: -2376.5404
A24: holiday_flag | B24: 15135.306 | C24: 6126.5915 | D24: 2.4704284 | E24: 0.014041828 | F24: 3079.5683 | G24: 27191.043 | H24: 3079.5683 | I24: 27191.043
A25: customer_rating | B25: 12622.239 | C25: 4446.6585 | D25: 2.8385897 | E25: 0.004835391 | F25: 3872.2275 | G25: 21372.251 | H25: 3872.2275 | I25: 21372.251
A26: is_east | B26: -21114.068 | C26: 6628.4006 | D26: -3.1853942 | E26: 0.0015951798 | F26: -34157.252 | G26: -8070.885 | H26: -34157.252 | I26: -8070.885
A27: is_west | B27: 4188.5303 | C27: 6808.6358 | D27: 0.61517908 | E27: 0.53889518 | F27: -9209.315 | G27: 17586.376 | H27: -9209.315 | I27: 17586.376
A28: is_north | B28: -11161.029 | C28: 7428.7812 | D28: -1.5024038 | E28: 0.13402748 | F28: -25779.179 | G28: 3457.1211 | H28: -25779.179 | I28: 3457.1211
... A31: is_mall | B31: 32837.454 | C31: 6156.8903 | D31: 5.333448 | E31: 1.8806351e-07 | F31: 20722.095 | G31: 44952.812 | H31: 20722.095 | I31: 44952.812

Sheet Predictions and Residuals
A1: RESIDUAL OUTPUT | D1: Colour Codes:
D2: Top 5
A3: Observation | B3: Predicted monthly_sales | C3: Residuals | D3: Bottom 5
A4: 1 | B4: 676950.78 | C4: -18118.162
A5: 2 | B5: 678940.45 | C5: -44504.447
A6: 3 | B6: 696062.01 | C6: -17339.946
A7: 4 | B7: 734539.8 | C7: -75619.501
A8: 5 | B8: 788243.3 | C8: -46901.855
A9: 6 | B9: 774017.4 | C9: -12182.058
A10: 7 | B10: 806787.12 | C10: -171.58219
A11: 8 | B11: 792772.96 | C11: 57391.305
A12: 9 | B12: 873192.2 | C12: 57389.499
A13: 10 | B13: 808208.56 | C13: -29197.616
A14: 11 | B14: 753973.23 | C14: -30912.469
A15: 12 | B15: 867771.31 | C15: 43020.632
... A323: 320 | B323: 557671.48 | C323: 1989.3606

Sheet Model Comparison
A1: Metric | B1: Simple Regression Model | C1: Column1 | D1: Multiple Regression Model
A2: Independent Variable | B2: marketing_spend | C2: footfall | D2: 14 variables
A3: Multiple R | B3: ='Simple Regression'!B4 -> 0.40895561 | C3: ='Simple Regression'!B25 -> 0.85807071 | D3: ='Multiple Regression'!B4 -> 0.92577345
A4: R Square | B4: ='Simple Regression'!B5 -> 0.16724469 | C4: ='Simple Regression'!B26 -> 0.73628534 | D4: ='Multiple Regression'!B5 -> 0.85705649
A5: Adjusted R Square | B5: ='Simple Regression'!B6 -> 0.16462596 | C5: ='Simple Regression'!B27 -> 0.73545605 | D5: ='Multiple Regression'!B6 -> 0.85049515
A6: Standard Error | B6: ='Simple Regression'!B7 -> 94846.034 | C6: ='Simple Regression'!B28 -> 53373.736 | D6: ='Multiple Regression'!B7 -> 40124.195
A7: Observations | B7: ='Simple Regression'!B8 -> 320 | C7: ='Simple Regression'!B29 -> 320 | D7: ='Multiple Regression'!B8 -> 320

Sheet data_dictionary
A1: Column | B1: Description
A2: store_id | B2: Unique store identifier.
A3: month | B3: Reporting month.
A4: region | B4: Business region.
A5: store_type | B5: Mall, High Street, Residential, or Airport.
A6: marketing_spend | B6: Monthly marketing spend for the store.
A7: footfall | B7: Monthly visitor count.
A8: avg_discount_pct | B8: Average discount percentage for the month.
A9: staff_count | B9: Number of store staff.
A10: inventory_availability_pct | B10: Average product availability percentage.
A11: competitor_distance_km | B11: Distance to nearest competitor.
A12: holiday_flag | B12: 1 if the month/store period had a meaningful holiday effect; otherwise 0.
... A15: monthly_profit | B15: Optional secondary business metric.

Sheet Sheet2
A2: median competitor distance = | D2: =MEDIAN('Cleaned Data'!J2:J321) -> 3.365
A4: average rating by store type
A5: airport | C5: =AVERAGEIF('Cleaned Data'!D2:D321, "Airport", 'Cleaned Data'!L2:L321) -> 3.7785714 | D5: 3.7785714
A6: high street | C6: =AVERAGEIF('Cleaned Data'!D2:D321, "High Street", 'Cleaned Data'!L2:L321) -> 3.8732759 | D6: 3.8752212
A7: mall | C7: =AVERAGEIF('Cleaned Data'!D2:D321, "Mall", 'Cleaned Data'!L2:L321) -> 3.9657895 | D7: 3.9666667
A8: residential | C8: =AVERAGEIF('Cleaned Data'!D2:D321, "Residential", 'Cleaned Data'!L2:L321) -> 3.989 | D8: 3.9927083
